Workbook

Sheet ReadMe
A1: SG consumables-per-treatment mapping (hypothetical)
A3: Purpose | B3: For each of the 81 services in SG-Confidential.xlsx, lists which of the 58 tracked consumables would be used, in what quantity, grouped by the client's 7 inventory categories.
A4: Status | B4: HYPOTHETICAL. Quantities are typical-practice estimates, not client data and not medical protocols. Have the client validate before anything is seeded.
A5: How to read | B5: Matrix = quick visual. Service_Consumables = one row per service/item, shaped like the ERD junction table (Services_Consumables). Kits = editable base recipes. Services = size multipliers. Items = units and pack sizes. Gaps and Flags = what is missing and what will break.
A6: How to tweak | B6: Edit blue cells only: Kits (base qty, scales, mode), Services (size multiplier), Items (type, pack size). Everything else recalculates.
A7: Modes | B7: Auto-deduct = consumed in the session. Aftercare (sell/dispense) = recommended product; deduct only if actually sold, via post-service sales. Overhead items (toilet tissue, hand soap) are not mapped.
A8: Types | B8: Countable = whole pieces (syringes, gloves), rounded UP. Bulk = fractions of a container (mL, g, cm, sheets); Stock units consumed = qty / pack size.
A9: Size multiplier | B9: Scales lines marked Y in Kits (e.g. Full Legs = 4x a small area, Whole Body TCA = 8x). Hygiene lines never scale.
A10: Not confirmed | B10: Items whose real use I had to guess are marked ASSUMED in Items (Cartridge, Capsugen, Nee Revive/Bright, CV/RF Tissue, Frozen Mask, Test Tube).

Sheet Items
A1: Items: what each of the 58 inventory items is and how it is counted
A2: Blue = assumption you can edit. Source of item names/categories: client SG-Confidential.xlsx (Consumables sheet). Unit/pack sizes are hypothetical.
A4: Item | B4: Category | C4: Type | D4: Stock unit | E4: Usage unit | F4: Pack size (usage units per stock unit) | G4: Role | H4: # services: auto-deduct | I4: # services: aftercare | J4: Assumption / note
A5: 1cc Syringe | B5: MEDICAL / INJECTION SUPPLIES | C5: Countable | D5: pc | E5: pc | F5: 1 | G5: Clinical consumable | H5: =INDEX(Matrix!$D$4:$BI$4,MATCH($A5,Matrix!$D$5:$BI$5,0)) -> 2 | I5: =COUNTIFS(Service_Consumables!$E$5:$E$856,$A5,Service_Consumables!$H$5:$H$856,"Aftercare (sell/dispense)") -> 0
A6: 3cc Syringe | B6: MEDICAL / INJECTION SUPPLIES | C6: Countable | D6: pc | E6: pc | F6: 1 | G6: Clinical consumable | H6: =INDEX(Matrix!$D$4:$BI$4,MATCH($A6,Matrix!$D$5:$BI$5,0)) -> 7 | I6: =COUNTIFS(Service_Consumables!$E$5:$E$856,$A6,Service_Consumables!$H$5:$H$856,"Aftercare (sell/dispense)") -> 0
A7: 10cc Syringe | B7: MEDICAL / INJECTION SUPPLIES | C7: Countable | D7: pc | E7: pc | F7: 1 | G7: Clinical consumable | H7: =INDEX(Matrix!$D$4:$BI$4,MATCH($A7,Matrix!$D$5:$BI$5,0)) -> 8 | I7: =COUNTIFS(Service_Consumables!$E$5:$E$856,$A7,Service_Consumables!$H$5:$H$856,"Aftercare (sell/dispense)") -> 0
A8: Scalp Vein Set | B8: MEDICAL / INJECTION SUPPLIES | C8: Countable | D8: pc | E8: pc | F8: 1 | G8: Clinical consumable | H8: =INDEX(Matrix!$D$4:$BI$4,MATCH($A8,Matrix!$D$5:$BI$5,0)) -> 2 | I8: =COUNTIFS(Service_Consumables!$E$5:$E$856,$A8,Service_Consumables!$H$5:$H$856,"Aftercare (sell/dispense)") -> 0
A9: Baby Needle | B9: MEDICAL / INJECTION SUPPLIES | C9: Countable | D9: pc | E9: pc | F9: 1 | G9: Clinical consumable | H9: =INDEX(Matrix!$D$4:$BI$4,MATCH($A9,Matrix!$D$5:$BI$5,0)) -> 6 | I9: =COUNTIFS(Service_Consumables!$E$5:$E$856,$A9,Service_Consumables!$H$5:$H$856,"Aftercare (sell/dispense)") -> 0 | J9: Assumed fine-gauge mesotherapy needle.
A10: 1cc BD Needle | B10: MEDICAL / INJECTION SUPPLIES | C10: Countable | D10: pc | E10: pc | F10: 1 | G10: Clinical consumable | H10: =INDEX(Matrix!$D$4:$BI$4,MATCH($A10,Matrix!$D$5:$BI$5,0)) -> 6 | I10: =COUNTIFS(Service_Consumables!$E$5:$E$856,$A10,Service_Consumables!$H$5:$H$856,"Aftercare (sell/dispense)") -> 0
A11: Cannula | B11: MEDICAL / INJECTION SUPPLIES | C11: Countable | D11: pc | E11: pc | F11: 1 | G11: Clinical consumable | H11: =INDEX(Matrix!$D$4:$BI$4,MATCH($A11,Matrix!$D$5:$BI$5,0)) -> 6 | I11: =COUNTIFS(Service_Consumables!$E$5:$E$856,$A11,Service_Consumables!$H$5:$H$856,"Aftercare (sell/dispense)") -> 0 | J11: Assumed IV cannula.
A12: Cartridge | B12: MEDICAL / INJECTION SUPPLIES | C12: Countable | D12: pc | E12: pc | F12: 1 | G12: Clinical consumable | H12: =INDEX(Matrix!$D$4:$BI$4,MATCH($A12,Matrix!$D$5:$BI$5,0)) -> 2 | I12: =COUNTIFS(Service_Consumables!$E$5:$E$856,$A12,Service_Consumables!$H$5:$H$856,"Aftercare (sell/dispense)") -> 0 | J12: ASSUMED microneedling / meso-device cartridge. Confirm with client.
A13: Test Tube | B13: MEDICAL / INJECTION SUPPLIES | C13: Countable | D13: pc | E13: pc | F13: 1 | G13: Clinical consumable | H13: =INDEX(Matrix!$D$4:$BI$4,MATCH($A13,Matrix!$D$5:$BI$5,0)) -> 6 | I13: =COUNTIFS(Service_Consumables!$E$5:$E$856,$A13,Service_Consumables!$H$5:$H$856,"Aftercare (sell/dispense)") -> 0 | J13: WEAKEST MAPPING: assumed cocktail-mixing vessel for mesotherapy. Confirm with client.
A14: Sterile Water | B14: MEDICAL / INJECTION SUPPLIES | C14: Countable | D14: ampule | E14: ampule | F14: 1 | G14: Clinical consumable | H14: =INDEX(Matrix!$D$4:$BI$4,MATCH($A14,Matrix!$D$5:$BI$5,0)) -> 10 | I14: =COUNTIFS(Service_Consumables!$E$5:$E$856,$A14,Service_Consumables!$H$5:$H$856,"Aftercare (sell/dispense)") -> 0 | J14: Assumed 10 mL ampule for dilution/reconstitution.
A15: Macroset (IV Set) | B15: MEDICAL / INJECTION SUPPLIES | C15: Countable | D15: pc | E15: pc | F15: 1 | G15: Clinical consumable | H15: =INDEX(Matrix!$D$4:$BI$4,MATCH($A15,Matrix!$D$5:$BI$5,0)) -> 6 | I15: =COUNTIFS(Service_Consumables!$E$5:$E$856,$A15,Service_Consumables!$H$5:$H$856,"Aftercare (sell/dispense)") -> 0
A16: Bouffant Cap | B16: DISPOSABLES & CLINIC CONSUMABLES | C16: Countable | D16: pc | E16: pc | F16: 1 | G16: Clinical consumable | H16: =INDEX(Matrix!$D$4:$BI$4,MATCH($A16,Matrix!$D$5:$BI$5,0)) -> 25 | I16: =COUNTIFS(Service_Consumables!$E$5:$E$856,$A16,Service_Consumables!$H$5:$H$856,"Aftercare (sell/dispense)") -> 0
A17: Disposable Mask | B17: DISPOSABLES & CLINIC CONSUMABLES | C17: Countable | D17: pc | E17: pc | F17: 1 | G17: Clinical consumable | H17: =INDEX(Matrix!$D$4:$BI$4,MATCH($A17,Matrix!$D$5:$BI$5,0)) -> 77 | I17: =COUNTIFS(Service_Consumables!$E$5:$E$856,$A17,Service_Consumables!$H$5:$H$856,"Aftercare (sell/dispense)") -> 0
A18: Latex Gloves (Small) | B18: DISPOSABLES & CLINIC CONSUMABLES | C18: Countable | D18: pair | E18: pair | F18: 1 | G18: Clinical consumable | H18: =INDEX(Matrix!$D$4:$BI$4,MATCH($A18,Matrix!$D$5:$BI$5,0)) -> 77 | I18: =COUNTIFS(Service_Consumables!$E$5:$E$856,$A18,Service_Consumables!$H$5:$H$856,"Aftercare (sell/dispense)") -> 0 | J18: Default glove size for every hands-on service (see Flags: glove size depends on the staff member, not the treatment).
A19: Latex Gloves (Medium) | B19: DISPOSABLES & CLINIC CONSUMABLES | C19: Countable | D19: pair | E19: pair | F19: 1 | G19: Clinical consumable | H19: =INDEX(Matrix!$D$4:$BI$4,MATCH($A19,Matrix!$D$5:$BI$5,0)) -> 0 | I19: =COUNTIFS(Service_Consumables!$E$5:$E$856,$A19,Service_Consumables!$H$5:$H$856,"Aftercare (sell/dispense)") -> 0 | J19: Deliberately unmapped: size depends on who performs the service. Handle by monthly Adjustment.
A20: Facial Tissue | B20: DISPOSABLES & CLINIC CONSUMABLES | C20: Bulk | D20: box | E20: sheet | F20: 200 | G20: Clinical consumable | H20: =INDEX(Matrix!$D$4:$BI$4,MATCH($A20,Matrix!$D$5:$BI$5,0)) -> 64 | I20: =COUNTIFS(Service_Consumables!$E$5:$E$856,$A20,Service_Consumables!$H$5:$H$856,"Aftercare (sell/dispense)") -> 0 | J20: Assumed 200-sheet box.
A21: Toilet Tissue | B21: DISPOSABLES & CLINIC CONSUMABLES | C21: Countable | D21: roll | E21: roll | F21: 1 | G21: Overhead (not per service) | H21: =INDEX(Matrix!$D$4:$BI$4,MATCH($A21,Matrix!$D$5:$BI$5,0)) -> 0 | I21: =COUNTIFS(Service_Consumables!$E$5:$E$856,$A21,Service_Consumables!$H$5:$H$856,"Aftercare (sell/dispense)") -> 0 | J21: General clinic use. Not mapped per service.
A22: CV/RF Tissue | B22: DISPOSABLES & CLINIC CONSUMABLES | C22: Bulk | D22: box | E22: sheet | F22: 100 | G22: Clinical consumable | H22: =INDEX(Matrix!$D$4:$BI$4,MATCH($A22,Matrix!$D$5:$BI$5,0)) -> 12 | I22: =COUNTIFS(Service_Consumables!$E$5:$E$856,$A22,Service_Consumables!$H$5:$H$856,"Aftercare (sell/dispense)") -> 0 | J22: ASSUMED disposable sheet used with RF / cavitation devices. Confirm.
A23: Cotton Roll | B23: DISPOSABLES & CLINIC CONSUMABLES | C23: Bulk | D23: roll | E23: g | F23: 400 | G23: Clinical consumable | H23: =INDEX(Matrix!$D$4:$BI$4,MATCH($A23,Matrix!$D$5:$BI$5,0)) -> 44 | I23: =COUNTIFS(Service_Consumables!$E$5:$E$856,$A23,Service_Consumables!$H$5:$H$856,"Aftercare (sell/dispense)") -> 0 | J23: Assumed 400 g roll.
A24: Cotton Applicator | B24: DISPOSABLES & CLINIC CONSUMABLES | C24: Bulk | D24: box | E24: pc | F24: 100 | G24: Clinical consumable | H24: =INDEX(Matrix!$D$4:$BI$4,MATCH($A24,Matrix!$D$5:$BI$5,0)) -> 38 | I24: =COUNTIFS(Service_Consumables!$E$5:$E$856,$A24,Service_Consumables!$H$5:$H$856,"Aftercare (sell/dispense)") -> 0 | J24: Assumed 100-pc box.
A25: Tongue Depressor | B25: DISPOSABLES & CLINIC CONSUMABLES | C25: Bulk | D25: box | E25: pc | F25: 100 | G25: Clinical consumable | H25: =INDEX(Matrix!$D$4:$BI$4,MATCH($A25,Matrix!$D$5:$BI$5,0)) -> 9 | I25: =COUNTIFS(Service_Consumables!$E$5:$E$856,$A25,Service_Consumables!$H$5:$H$856,"Aftercare (sell/dispense)") -> 0 | J25: Used as a spatula to scoop masks/creams.
A26: Transpore Tape | B26: DISPOSABLES & CLINIC CONSUMABLES | C26: Bulk | D26: roll | E26: cm | F26: 914 | G26: Clinical consumable | H26: =INDEX(Matrix!$D$4:$BI$4,MATCH($A26,Matrix!$D$5:$BI$5,0)) -> 14 | I26: =COUNTIFS(Service_Consumables!$E$5:$E$856,$A26,Service_Consumables!$H$5:$H$856,"Aftercare (sell/dispense)") -> 0 | J26: Assumed 1 in x 10 yd roll.
A27: Cling Wrap | B27: DISPOSABLES & CLINIC CONSUMABLES | C27: Bulk | D27: roll | E27: cm | F27: 3000 | G27: Clinical consumable | H27: =INDEX(Matrix!$D$4:$BI$4,MATCH($A27,Matrix!$D$5:$BI$5,0)) -> 15 | I27: =COUNTIFS(Service_Consumables!$E$5:$E$856,$A27,Service_Consumables!$H$5:$H$856,"Aftercare (sell/dispense)") -> 0 | J27: Assumed 30 m roll. Occlusion for numbing cream; wrap for paraffin.
A28: Gauze | B28: DISPOSABLES & CLINIC CONSUMABLES | C28: Bulk | D28: pack | E28: pc | F28: 100 | G28: Clinical consumable | H28: =INDEX(Matrix!$D$4:$BI$4,MATCH($A28,Matrix!$D$5:$BI$5,0)) -> 22 | I28: =COUNTIFS(Service_Consumables!$E$5:$E$856,$A28,Service_Consumables!$H$5:$H$856,"Aftercare (sell/dispense)") -> 0 | J28: Assumed 100-pc pack.
A29: Sterile Gauze | B29: DISPOSABLES & CLINIC CONSUMABLES | C29: Countable | D29: pc | E29: pc | F29: 1 | G29: Clinical consumable | H29: =INDEX(Matrix!$D$4:$BI$4,MATCH($A29,Matrix!$D$5:$BI$5,0)) -> 19 | I29: =COUNTIFS(Service_Consumables!$E$5:$E$856,$A29,Service_Consumables!$H$5:$H$856,"Aftercare (sell/dispense)") -> 0 | J29: Assumed individually packed.
... A32: Toner | B32: FACIAL / TREATMENT PREP PRODUCTS | C32: Bulk | D32: bottle | E32: mL | F32: 500 | G32: Clinical consumable | H32: =INDEX(Matrix!$D$4:$BI$4,MATCH($A32,Matrix!$D$5:$BI$5,0)) -> 11 | I32: =COUNTIFS(Service_Consumables!$E$5:$E$856,$A32,Service_Consumables!$H$5:$H$856,"Aftercare (sell/dispense)") -> 0 | J32: Assumed clinic-size 500 mL bottle.
A33: Clarifying Toner | B33: FACIAL / TREATMENT PREP PRODUCTS | C33: Bulk | D33: bottle | E33: mL | F33: 500 | G33: Clinical consumable | H33: =INDEX(Matrix!$D$4:$BI$4,MATCH($A33,Matrix!$D$5:$BI$5,0)) -> 15 | I33: =COUNTIFS(Service_Consumables!$E$5:$E$856,$A33,Service_Consumables!$H$5:$H$856,"Aftercare (sell/dispense)") -> 0
A34: Acne Buster Toner | B34: FACIAL / TREATMENT PREP PRODUCTS | C34: Bulk | D34: bottle | E34: mL | F34: 250 | G34: Clinical consumable | H34: =INDEX(Matrix!$D$4:$BI$4,MATCH($A34,Matrix!$D$5:$BI$5,0)) -> 2 | I34: =COUNTIFS(Service_Consumables!$E$5:$E$856,$A34,Service_Consumables!$H$5:$H$856,"Aftercare (sell/dispense)") -> 0
A35: Glycolic Peeling Toner | B35: FACIAL / TREATMENT PREP PRODUCTS | C35: Bulk | D35: bottle | E35: mL | F35: 250 | G35: Clinical consumable | H35: =INDEX(Matrix!$D$4:$BI$4,MATCH($A35,Matrix!$D$5:$BI$5,0)) -> 2 | I35: =COUNTIFS(Service_Consumables!$E$5:$E$856,$A35,Service_Consumables!$H$5:$H$856,"Aftercare (sell/dispense)") -> 0
A36: Hypo Liquid Soap | B36: FACIAL / TREATMENT PREP PRODUCTS | C36: Bulk | D36: bottle | E36: mL | F36: 500 | G36: Clinical consumable | H36: =INDEX(Matrix!$D$4:$BI$4,MATCH($A36,Matrix!$D$5:$BI$5,0)) -> 11 | I36: =COUNTIFS(Service_Consumables!$E$5:$E$856,$A36,Service_Consumables!$H$5:$H$856,"Aftercare (sell/dispense)") -> 0 | J36: Assumed facial cleanser.
A37: Facial Scrub | B37: FACIAL / TREATMENT PREP PRODUCTS | C37: Bulk | D37: tub | E37: g | F37: 250 | G37: Clinical consumable | H37: =INDEX(Matrix!$D$4:$BI$4,MATCH($A37,Matrix!$D$5:$BI$5,0)) -> 3 | I37: =COUNTIFS(Service_Consumables!$E$5:$E$856,$A37,Service_Consumables!$H$5:$H$856,"Aftercare (sell/dispense)") -> 0
A38: Hand Soap | B38: FACIAL / TREATMENT PREP PRODUCTS | C38: Bulk | D38: bottle | E38: mL | F38: 500 | G38: Overhead (not per service) | H38: =INDEX(Matrix!$D$4:$BI$4,MATCH($A38,Matrix!$D$5:$BI$5,0)) -> 0 | I38: =COUNTIFS(Service_Consumables!$E$5:$E$856,$A38,Service_Consumables!$H$5:$H$856,"Aftercare (sell/dispense)") -> 0 | J38: General hygiene. Not mapped per service.
A39: Gold Mask | B39: FACIAL TREATMENT PRODUCTS (PROFESSIONAL USE) | C39: Bulk | D39: tub | E39: g | F39: 500 | G39: Clinical consumable | H39: =INDEX(Matrix!$D$4:$BI$4,MATCH($A39,Matrix!$D$5:$BI$5,0)) -> 1 | I39: =COUNTIFS(Service_Consumables!$E$5:$E$856,$A39,Service_Consumables!$H$5:$H$856,"Aftercare (sell/dispense)") -> 0 | J39: Unit depends on product form (tub vs sheet). Confirm.
A40: Collagen Gold Mask | B40: FACIAL TREATMENT PRODUCTS (PROFESSIONAL USE) | C40: Bulk | D40: tub | E40: g | F40: 500 | G40: Clinical consumable | H40: =INDEX(Matrix!$D$4:$BI$4,MATCH($A40,Matrix!$D$5:$BI$5,0)) -> 1 | I40: =COUNTIFS(Service_Consumables!$E$5:$E$856,$A40,Service_Consumables!$H$5:$H$856,"Aftercare (sell/dispense)") -> 0 | J40: Unit depends on product form. Confirm.
A41: Hydra Moist Mask | B41: FACIAL TREATMENT PRODUCTS (PROFESSIONAL USE) | C41: Bulk | D41: tub | E41: g | F41: 500 | G41: Clinical consumable | H41: =INDEX(Matrix!$D$4:$BI$4,MATCH($A41,Matrix!$D$5:$BI$5,0)) -> 7 | I41: =COUNTIFS(Service_Consumables!$E$5:$E$856,$A41,Service_Consumables!$H$5:$H$856,"Aftercare (sell/dispense)") -> 0 | J41: Unit depends on product form. Confirm.
A42: Frozen Mask | B42: FACIAL TREATMENT PRODUCTS (PROFESSIONAL USE) | C42: Bulk | D42: tub | E42: g | F42: 500 | G42: Clinical consumable | H42: =INDEX(Matrix!$D$4:$BI$4,MATCH($A42,Matrix!$D$5:$BI$5,0)) -> 14 | I42: =COUNTIFS(Service_Consumables!$E$5:$E$856,$A42,Service_Consumables!$H$5:$H$856,"Aftercare (sell/dispense)") -> 0 | J42: ASSUMED cooling/soothing mask. Confirm.
A43: RF Cream | B43: FACIAL TREATMENT PRODUCTS (PROFESSIONAL USE) | C43: Bulk | D43: tub | E43: g | F43: 500 | G43: Clinical consumable | H43: =INDEX(Matrix!$D$4:$BI$4,MATCH($A43,Matrix!$D$5:$BI$5,0)) -> 9 | I43: =COUNTIFS(Service_Consumables!$E$5:$E$856,$A43,Service_Consumables!$H$5:$H$856,"Aftercare (sell/dispense)") -> 0 | J43: Conductive cream for RF body tightening.
...

Sheet Kits
A1: Kits: reusable consumable bundles (base quantity at size multiplier = 1)
A2: Blue = hypothetical quantity. "Scales" = Y means quantity is multiplied by the service size multiplier. Mode: Auto-deduct = consumed in session; Aftercare = only if sold/dispensed.
A4: Kit | B4: Item | C4: Base qty (usage units) | D4: Scales with area (Y/N) | E4: Mode | F4: Kit purpose
A5: K_HYG | B5: Disposable Mask | C5: 1 | D5: N | E5: Auto-deduct | F5: Hygiene basics for any hands-on service
A6: K_HYG | B6: Latex Gloves (Small) | C6: 1 | D6: N | E6: Auto-deduct | F6: Hygiene basics for any hands-on service
A7: K_HYG | B7: Alcohol | C7: 5 | D7: N | E7: Auto-deduct | F7: Hygiene basics for any hands-on service
A8: K_CAP | B8: Bouffant Cap | C8: 1 | D8: N | E8: Auto-deduct | F8: Client hair cover
A9: K_FACE_PREP | B9: Bouffant Cap | C9: 1 | D9: N | E9: Auto-deduct | F9: Cap, cleanse, tone, tissue
A10: K_FACE_PREP | B10: Hypo Liquid Soap | C10: 5 | D10: N | E10: Auto-deduct | F10: Cap, cleanse, tone, tissue
A11: K_FACE_PREP | B11: Toner | C11: 10 | D11: N | E11: Auto-deduct | F11: Cap, cleanse, tone, tissue
A12: K_FACE_PREP | B12: Cotton Roll | C12: 5 | D12: N | E12: Auto-deduct | F12: Cap, cleanse, tone, tissue
A13: K_FACE_PREP | B13: Facial Tissue | C13: 6 | D13: N | E13: Auto-deduct | F13: Cap, cleanse, tone, tissue
A14: K_EXTRACT | B14: Cotton Applicator | C14: 4 | D14: N | E14: Auto-deduct | F14: Extraction step
A15: K_EXTRACT | B15: Gauze | C15: 2 | D15: N | E15: Auto-deduct | F15: Extraction step
A16: K_EXTRACT | B16: Alcohol | C16: 5 | D16: N | E16: Auto-deduct | F16: Extraction step
... A163: K_BT_BFR | B163: Facial Tissue | C163: 4 | D163: N | E163: Auto-deduct | F163: Combined BT + BFR

Sheet Services
A1: Services: 81 services from the client price list
A2: ID is a placeholder (row order). Remap to services.service_id once the services table is seeded. Prices copied from client Treatment sheet.
A4: ID | B4: Family | C4: Service | D4: List price (PHP) | E4: Kits used | F4: Size multiplier | G4: Notes | H4: # consumable lines | I4: # auto-deduct lines
A5: 1 | B5: Eyelash Extension | C5: Classic | D5: 600 | E5: K_HYG+K_LASH | F5: 1 | H5: =COUNTIF(Service_Consumables!$A$5:$A$856,$A5) -> 10 | I5: =COUNTIFS(Service_Consumables!$A$5:$A$856,$A5,Service_Consumables!$H$5:$H$856,"Auto-deduct") -> 10
A6: 2 | B6: Eyelash Extension | C6: Hybrid | D6: 800 | E6: K_HYG+K_LASH | F6: 1 | H6: =COUNTIF(Service_Consumables!$A$5:$A$856,$A6) -> 10 | I6: =COUNTIFS(Service_Consumables!$A$5:$A$856,$A6,Service_Consumables!$H$5:$H$856,"Auto-deduct") -> 10
A7: 3 | B7: Eyelash Extension | C7: Volume | D7: 1300 | E7: K_HYG+K_LASH | F7: 1 | H7: =COUNTIF(Service_Consumables!$A$5:$A$856,$A7) -> 10 | I7: =COUNTIFS(Service_Consumables!$A$5:$A$856,$A7,Service_Consumables!$H$5:$H$856,"Auto-deduct") -> 10
A8: 4 | B8: Eyelash Extension | C8: Mega Volume | D8: 1700 | E8: K_HYG+K_LASH | F8: 1 | H8: =COUNTIF(Service_Consumables!$A$5:$A$856,$A8) -> 10 | I8: =COUNTIFS(Service_Consumables!$A$5:$A$856,$A8,Service_Consumables!$H$5:$H$856,"Auto-deduct") -> 10
A9: 5 | B9: Eyelash Extension | C9: Infill | D9: 350 | E9: K_HYG+K_LASH | F9: 1 | G9: Same list as a full set; a real infill uses less. Tune after client input. | H9: =COUNTIF(Service_Consumables!$A$5:$A$856,$A9) -> 10 | I9: =COUNTIFS(Service_Consumables!$A$5:$A$856,$A9,Service_Consumables!$H$5:$H$856,"Auto-deduct") -> 10
A10: 6 | B10: Eyelash Extension | C10: Removal | D10: 500 | E10: K_HYG+K_LASH_REMOVE | F10: 1 | H10: =COUNTIF(Service_Consumables!$A$5:$A$856,$A10) -> 8 | I10: =COUNTIFS(Service_Consumables!$A$5:$A$856,$A10,Service_Consumables!$H$5:$H$856,"Auto-deduct") -> 8
A11: 7 | B11: Threading Services | C11: Eyebrow | D11: 200 | E11: K_HYG+K_THREAD | F11: 1 | H11: =COUNTIF(Service_Consumables!$A$5:$A$856,$A11) -> 7 | I11: =COUNTIFS(Service_Consumables!$A$5:$A$856,$A11,Service_Consumables!$H$5:$H$856,"Auto-deduct") -> 7
A12: 8 | B12: Threading Services | C12: Upper Lip | D12: 200 | E12: K_HYG+K_THREAD | F12: 1 | H12: =COUNTIF(Service_Consumables!$A$5:$A$856,$A12) -> 7 | I12: =COUNTIFS(Service_Consumables!$A$5:$A$856,$A12,Service_Consumables!$H$5:$H$856,"Auto-deduct") -> 7
A13: 9 | B13: Threading Services | C13: Lower Lip | D13: 200 | E13: K_HYG+K_THREAD | F13: 1 | H13: =COUNTIF(Service_Consumables!$A$5:$A$856,$A13) -> 7 | I13: =COUNTIFS(Service_Consumables!$A$5:$A$856,$A13,Service_Consumables!$H$5:$H$856,"Auto-deduct") -> 7
A14: 10 | B14: Threading Services | C14: Combo | D14: 500 | E14: K_HYG+K_THREAD | F14: 2.5 | G14: Eyebrow + upper + lower lip. | H14: =COUNTIF(Service_Consumables!$A$5:$A$856,$A14) -> 7 | I14: =COUNTIFS(Service_Consumables!$A$5:$A$856,$A14,Service_Consumables!$H$5:$H$856,"Auto-deduct") -> 7
A15: 11 | B15: Hair Removal (IPL-HR) | C15: Underarms | D15: 2000 | E15: K_HYG+K_IPL+K_AFT_UNDERARM | F15: 1 | H15: =COUNTIF(Service_Consumables!$A$5:$A$856,$A15) -> 10 | I15: =COUNTIFS(Service_Consumables!$A$5:$A$856,$A15,Service_Consumables!$H$5:$H$856,"Auto-deduct") -> 8
A16: 12 | B16: Hair Removal (IPL-HR) | C16: Bikini Line | D16: 2000 | E16: K_HYG+K_IPL+K_NUMB+K_AFT_IRRIT | F16: 1 | H16: =COUNTIF(Service_Consumables!$A$5:$A$856,$A16) -> 11 | I16: =COUNTIFS(Service_Consumables!$A$5:$A$856,$A16,Service_Consumables!$H$5:$H$856,"Auto-deduct") -> 10
A17: 13 | B17: Hair Removal (IPL-HR) | C17: Face | D17: 2000 | E17: K_HYG+K_IPL+K_IPL_FACE | F17: 1 | H17: =COUNTIF(Service_Consumables!$A$5:$A$856,$A17) -> 10 | I17: =COUNTIFS(Service_Consumables!$A$5:$A$856,$A17,Service_Consumables!$H$5:$H$856,"Auto-deduct") -> 10
A18: 14 | B18: Hair Removal (IPL-HR) | C18: Upper Lip | D18: 2000 | E18: K_HYG+K_IPL+K_CAP | F18: 0.5 | H18: =COUNTIF(Service_Consumables!$A$5:$A$856,$A18) -> 9 | I18: =COUNTIFS(Service_Consumables!$A$5:$A$856,$A18,Service_Consumables!$H$5:$H$856,"Auto-deduct") -> 9
A19: 15 | B19: Hair Removal (IPL-HR) | C19: Full Legs | D19: 10000 | E19: K_HYG+K_IPL | F19: 4 | G19: One razor assumed for the whole session. | H19: =COUNTIF(Service_Consumables!$A$5:$A$856,$A19) -> 8 | I19: =COUNTIFS(Service_Consumables!$A$5:$A$856,$A19,Service_Consumables!$H$5:$H$856,"Auto-deduct") -> 8
A20: 16 | B20: Hair Removal (IPL-HR) | C20: Brazilian | D20: 4000 | E20: K_HYG+K_IPL+K_NUMB+K_AFT_IRRIT | F20: 1.5 | H20: =COUNTIF(Service_Consumables!$A$5:$A$856,$A20) -> 11 | I20: =COUNTIFS(Service_Consumables!$A$5:$A$856,$A20,Service_Consumables!$H$5:$H$856,"Auto-deduct") -> 10
A21: 17 | B21: Hair Removal (IPL-HR) | C21: Arms | D21: 4000 | E21: K_HYG+K_IPL | F21: 2 | H21: =COUNTIF(Service_Consumables!$A$5:$A$856,$A21) -> 8 | I21: =COUNTIFS(Service_Consumables!$A$5:$A$856,$A21,Service_Consumables!$H$5:$H$856,"Auto-deduct") -> 8
A22: 18 | B22: Hair Removal (IPL-HR) | C22: Half Legs | D22: 4000 | E22: K_HYG+K_IPL | F22: 2 | H22: =COUNTIF(Service_Consumables!$A$5:$A$856,$A22) -> 8 | I22: =COUNTIFS(Service_Consumables!$A$5:$A$856,$A22,Service_Consumables!$H$5:$H$856,"Auto-deduct") -> 8
A23: 19 | B23: Hair Removal (IPL-HR) | C23: Chest | D23: 4000 | E23: K_HYG+K_IPL | F23: 2 | H23: =COUNTIF(Service_Consumables!$A$5:$A$856,$A23) -> 8 | I23: =COUNTIFS(Service_Consumables!$A$5:$A$856,$A23,Service_Consumables!$H$5:$H$856,"Auto-deduct") -> 8
A24: 20 | B24: Electrocautery (ECT) | C24: Warts & Milia Removal | D24: 3000 | E24: K_HYG+K_CAP+K_ECT | F24: 1 | G24: Cautery tips / probes are not in the inventory list. | H24: =COUNTIF(Service_Consumables!$A$5:$A$856,$A24) -> 10 | I24: =COUNTIFS(Service_Consumables!$A$5:$A$856,$A24,Service_Consumables!$H$5:$H$856,"Auto-deduct") -> 9
A25: 21 | B25: Paraffin Therapy | C25: Hands | D25: 299 | E25: K_HYG+K_PARAFFIN | F25: 1 | H25: =COUNTIF(Service_Consumables!$A$5:$A$856,$A25) -> 6 | I25: =COUNTIFS(Service_Consumables!$A$5:$A$856,$A25,Service_Consumables!$H$5:$H$856,"Auto-deduct") -> 6
A26: 22 | B26: Paraffin Therapy | C26: Foot | D26: 349 | E26: K_HYG+K_PARAFFIN | F26: 1 | H26: =COUNTIF(Service_Consumables!$A$5:$A$856,$A26) -> 6 | I26: =COUNTIFS(Service_Consumables!$A$5:$A$856,$A26,Service_Consumables!$H$5:$H$856,"Auto-deduct") -> 6
A27: 23 | B27: Paraffin Therapy | C27: Hand & Foot | D27: 599 | E27: K_HYG+K_PARAFFIN | F27: 2 | H27: =COUNTIF(Service_Consumables!$A$5:$A$856,$A27) -> 6 | I27: =COUNTIFS(Service_Consumables!$A$5:$A$856,$A27,Service_Consumables!$H$5:$H$856,"Auto-deduct") -> 6
A28: 24 | B28: Foot Treatment | C28: Foot Spa | D28: 399 | E28: K_HYG+K_FOOTSPA | F28: 1 | H28: =COUNTIF(Service_Consumables!$A$5:$A$856,$A28) -> 7 | I28: =COUNTIFS(Service_Consumables!$A$5:$A$856,$A28,Service_Consumables!$H$5:$H$856,"Auto-deduct") -> 7
A29: 25 | B29: Foot Treatment | C29: Pedicure | D29: 299 | E29: K_HYG+K_PEDI | F29: 1 | H29: =COUNTIF(Service_Consumables!$A$5:$A$856,$A29) -> 9 | I29: =COUNTIFS(Service_Consumables!$A$5:$A$856,$A29,Service_Consumables!$H$5:$H$856,"Auto-deduct") -> 9
A30: 26 | B30: Foot Treatment | C30: Pedicure w/ Foot Spa | D30: 649 | E30: K_HYG+K_PEDI+K_FOOTSPA | F30: 1 | H30: =COUNTIF(Service_Consumables!$A$5:$A$856,$A30) -> 13 | I30: =COUNTIFS(Service_Consumables!$A$5:$A$856,$A30,Service_Consumables!$H$5:$H$856,"Auto-deduct") -> 13
A31: 27 | B31: Foot Treatment | C31: Pedicure w/ Foot Spa (Premium) | D31: 799 | E31: K_HYG+K_PEDI+K_FOOTSPA+K_PREMIUM | F31: 1 | G31: Client sheet lists two rows named "Pedicure w/ Foot Spa"; second one labelled Premium here. | H31: =COUNTIF(Service_Consumables!$A$5:$A$856,$A31) -> 15 | I31: =COUNTIFS(Service_Consumables!$A$5:$A$856,$A31,Service_Consumables!$H$5:$H$856,"Auto-deduct") -> 15
A32: 28 | B32: Drip / Shot (ED/GS) | C32: Anti-Aging Drip | D32: 3000 | E32: K_HYG+K_DRIP | F32: 1 | H32: =COUNTIF(Service_Consumables!$A$5:$A$856,$A32) -> 9 | I32: =COUNTIFS(Service_Consumables!$A$5:$A$856,$A32,Service_Consumables!$H$5:$H$856,"Auto-deduct") -> 9
A33: 29 | B33: Drip / Shot (ED/GS) | C33: Immune Booster Drip | D33: 3000 | E33: K_HYG+K_DRIP | F33: 1 | H33: =COUNTIF(Service_Consumables!$A$5:$A$856,$A33) -> 9 | I33: =COUNTIFS(Service_Consumables!$A$5:$A$856,$A33,Service_Consumables!$H$5:$H$856,"Auto-deduct") -> 9
A34: 30 | B34: Drip / Shot (ED/GS) | C34: Slimming Drip | D34: 3000 | E34: K_HYG+K_DRIP | F34: 1 | H34: =COUNTIF(Service_Consumables!$A$5:$A$856,$A34) -> 9 | I34: =COUNTIFS(Service_Consumables!$A$5:$A$856,$A34,Service_Consumables!$H$5:$H$856,"Auto-deduct") -> 9
A35: 31 | B35: Drip / Shot (ED/GS) | C35: Whitening Drip | D35: 3000 | E35: K_HYG+K_DRIP+K_AFT_WHITEN | F35: 1 | H35: =COUNTIF(Service_Consumables!$A$5:$A$856,$A35) -> 11 | I35: =COUNTIFS(Service_Consumables!$A$5:$A$856,$A35,Service_Consumables!$H$5:$H$856,"Auto-deduct") -> 9
A36: 32 | B36: Drip / Shot (ED/GS) | C36: 3-in-1 Drip | D36: 4000 | E36: K_HYG+K_DRIP | F36: 1 | H36: =COUNTIF(Service_Consumables!$A$5:$A$856,$A36) -> 9 | I36: =COUNTIFS(Service_Consumables!$A$5:$A$856,$A36,Service_Consumables!$H$5:$H$856,"Auto-deduct") -> 9
A37: 33 | B37: Drip / Shot (ED/GS) | C37: Gluta Shot w/ Vit. C | D37: 2000 | E37: K_HYG+K_SHOT+K_SHOT_VITC+K_AFT_BARLEY | F37: 1 | H37: =COUNTIF(Service_Consumables!$A$5:$A$856,$A37) -> 10 | I37: =COUNTIFS(Service_Consumables!$A$5:$A$856,$A37,Service_Consumables!$H$5:$H$856,"Auto-deduct") -> 9
A38: 34 | B38: Drip / Shot (ED/GS) | C38: Gluta Shot | D38: 1000 | E38: K_HYG+K_SHOT+K_AFT_BARLEY | F38: 1 | H38: =COUNTIF(Service_Consumables!$A$5:$A$856,$A38) -> 9 | I38: =COUNTIFS(Service_Consumables!$A$5:$A$856,$A38,Service_Consumables!$H$5:$H$856,"Auto-deduct") -> 8
A39: 35 | B39: Drip / Shot (ED/GS) | C39: Hikari Drip | D39: 4500 | E39: K_HYG+K_DRIP | F39: 1 | H39: =COUNTIF(Service_Consumables!$A$5:$A$856,$A39) -> 9 | I39: =COUNTIFS(Service_Consumables!$A$5:$A$856,$A39,Service_Consumables!$H$5:$H$856,"Auto-deduct") -> 9
A40: 36 | B40: Mesotherapy (MT) | C40: Face | D40: 3000 | E40: K_HYG+K_FACE_PREP+K_MESO | F40: 1 | H40: =COUNTIF(Service_Consumables!$A$5:$A$856,$A40) -> 15 | I40: =COUNTIFS(Service_Consumables!$A$5:$A$856,$A40,Service_Consumables!$H$5:$H$856,"Auto-deduct") -> 15
A41: 37 | B41: Mesotherapy (MT) | C41: Face w/ V-Lifting | D41: 3000 | E41: K_HYG+K_FACE_PREP+K_MESO+K_VLIFT_TOOLS | F41: 1 | H41: =COUNTIF(Service_Consumables!$A$5:$A$856,$A41) -> 18 | I41: =COUNTIFS(Service_Consumables!$A$5:$A$856,$A41,Service_Consumables!$H$5:$H$856,"Auto-deduct") -> 18
...

Sheet Service_Consumables
A1: Service_Consumables: one row per (service, item). Maps to the ERD junction table
A2: Formulas pull item info, base qty and size multiplier. Qty rounds UP for countable items. Stock units consumed = Qty / pack size.
A4: Service ID | B4: Service | C4: Family | D4: Kit | E4: Item | F4: Item category | G4: Type | H4: Mode | I4: Scales (Y/N) | J4: Base qty | K4: Size mult | L4: Qty (usage units) | M4: Usage unit | N4: Stock units consumed | O4: Notes
A5: 1 | B5: Classic | C5: Eyelash Extension | D5: K_HYG | E5: Disposable Mask | F5: =INDEX(Items!$B$5:$B$62,MATCH($E5,Items!$A$5:$A$62,0)) -> DISPOSABLES & CLINIC CONSUMABLES | G5: =INDEX(Items!$C$5:$C$62,MATCH($E5,Items!$A$5:$A$62,0)) -> Countable | H5: Auto-deduct | I5: N | J5: =SUMIFS(Kits!$C$5:$C$163,Kits!$A$5:$A$163,$D5,Kits!$B$5:$B$163,$E5) -> 1 | K5: =INDEX(Services!$F$5:$F$85,MATCH($A5,Services!$A$5:$A$85,0)) -> 1 | L5: =IF($H5="Auto-deduct",IF($G5="Countable",ROUNDUP($J5*IF($I5="Y",$K5,1),0),ROUND($J5*IF($I5="Y",$K5,1),1)),$J5) -> 1 | M5: =INDEX(Items!$E$5:$E$62,MATCH($E5,Items!$A$5:$A$62,0)) -> pc | N5: =ROUND($L5/INDEX(Items!$F$5:$F$62,MATCH($E5,Items!$A$5:$A$62,0)),4) -> 1
A6: 1 | B6: Classic | C6: Eyelash Extension | D6: K_HYG | E6: Latex Gloves (Small) | F6: =INDEX(Items!$B$5:$B$62,MATCH($E6,Items!$A$5:$A$62,0)) -> DISPOSABLES & CLINIC CONSUMABLES | G6: =INDEX(Items!$C$5:$C$62,MATCH($E6,Items!$A$5:$A$62,0)) -> Countable | H6: Auto-deduct | I6: N | J6: =SUMIFS(Kits!$C$5:$C$163,Kits!$A$5:$A$163,$D6,Kits!$B$5:$B$163,$E6) -> 1 | K6: =INDEX(Services!$F$5:$F$85,MATCH($A6,Services!$A$5:$A$85,0)) -> 1 | L6: =IF($H6="Auto-deduct",IF($G6="Countable",ROUNDUP($J6*IF($I6="Y",$K6,1),0),ROUND($J6*IF($I6="Y",$K6,1),1)),$J6) -> 1 | M6: =INDEX(Items!$E$5:$E$62,MATCH($E6,Items!$A$5:$A$62,0)) -> pair | N6: =ROUND($L6/INDEX(Items!$F$5:$F$62,MATCH($E6,Items!$A$5:$A$62,0)),4) -> 1
A7: 1 | B7: Classic | C7: Eyelash Extension | D7: K_HYG | E7: Alcohol | F7: =INDEX(Items!$B$5:$B$62,MATCH($E7,Items!$A$5:$A$62,0)) -> DISPOSABLES & CLINIC CONSUMABLES | G7: =INDEX(Items!$C$5:$C$62,MATCH($E7,Items!$A$5:$A$62,0)) -> Bulk | H7: Auto-deduct | I7: N | J7: =SUMIFS(Kits!$C$5:$C$163,Kits!$A$5:$A$163,$D7,Kits!$B$5:$B$163,$E7) -> 5 | K7: =INDEX(Services!$F$5:$F$85,MATCH($A7,Services!$A$5:$A$85,0)) -> 1 | L7: =IF($H7="Auto-deduct",IF($G7="Countable",ROUNDUP($J7*IF($I7="Y",$K7,1),0),ROUND($J7*IF($I7="Y",$K7,1),1)),$J7) -> 5 | M7: =INDEX(Items!$E$5:$E$62,MATCH($E7,Items!$A$5:$A$62,0)) -> mL | N7: =ROUND($L7/INDEX(Items!$F$5:$F$62,MATCH($E7,Items!$A$5:$A$62,0)),4) -> 0.01
A8: 1 | B8: Classic | C8: Eyelash Extension | D8: K_LASH | E8: Bouffant Cap | F8: =INDEX(Items!$B$5:$B$62,MATCH($E8,Items!$A$5:$A$62,0)) -> DISPOSABLES & CLINIC CONSUMABLES | G8: =INDEX(Items!$C$5:$C$62,MATCH($E8,Items!$A$5:$A$62,0)) -> Countable | H8: Auto-deduct | I8: N | J8: =SUMIFS(Kits!$C$5:$C$163,Kits!$A$5:$A$163,$D8,Kits!$B$5:$B$163,$E8) -> 1 | K8: =INDEX(Services!$F$5:$F$85,MATCH($A8,Services!$A$5:$A$85,0)) -> 1 | L8: =IF($H8="Auto-deduct",IF($G8="Countable",ROUNDUP($J8*IF($I8="Y",$K8,1),0),ROUND($J8*IF($I8="Y",$K8,1),1)),$J8) -> 1 | M8: =INDEX(Items!$E$5:$E$62,MATCH($E8,Items!$A$5:$A$62,0)) -> pc | N8: =ROUND($L8/INDEX(Items!$F$5:$F$62,MATCH($E8,Items!$A$5:$A$62,0)),4) -> 1
A9: 1 | B9: Classic | C9: Eyelash Extension | D9: K_LASH | E9: Cotton Applicator | F9: =INDEX(Items!$B$5:$B$62,MATCH($E9,Items!$A$5:$A$62,0)) -> DISPOSABLES & CLINIC CONSUMABLES | G9: =INDEX(Items!$C$5:$C$62,MATCH($E9,Items!$A$5:$A$62,0)) -> Bulk | H9: Auto-deduct | I9: N | J9: =SUMIFS(Kits!$C$5:$C$163,Kits!$A$5:$A$163,$D9,Kits!$B$5:$B$163,$E9) -> 4 | K9: =INDEX(Services!$F$5:$F$85,MATCH($A9,Services!$A$5:$A$85,0)) -> 1 | L9: =IF($H9="Auto-deduct",IF($G9="Countable",ROUNDUP($J9*IF($I9="Y",$K9,1),0),ROUND($J9*IF($I9="Y",$K9,1),1)),$J9) -> 4 | M9: =INDEX(Items!$E$5:$E$62,MATCH($E9,Items!$A$5:$A$62,0)) -> pc | N9: =ROUND($L9/INDEX(Items!$F$5:$F$62,MATCH($E9,Items!$A$5:$A$62,0)),4) -> 0.04
A10: 1 | B10: Classic | C10: Eyelash Extension | D10: K_LASH | E10: Cotton Roll | F10: =INDEX(Items!$B$5:$B$62,MATCH($E10,Items!$A$5:$A$62,0)) -> DISPOSABLES & CLINIC CONSUMABLES | G10: =INDEX(Items!$C$5:$C$62,MATCH($E10,Items!$A$5:$A$62,0)) -> Bulk | H10: Auto-deduct | I10: N | J10: =SUMIFS(Kits!$C$5:$C$163,Kits!$A$5:$A$163,$D10,Kits!$B$5:$B$163,$E10) -> 3 | K10: =INDEX(Services!$F$5:$F$85,MATCH($A10,Services!$A$5:$A$85,0)) -> 1 | L10: =IF($H10="Auto-deduct",IF($G10="Countable",ROUNDUP($J10*IF($I10="Y",$K10,1),0),ROUND($J10*IF($I10="Y",$K10,1),1)),$J10) -> 3 | M10: =INDEX(Items!$E$5:$E$62,MATCH($E10,Items!$A$5:$A$62,0)) -> g | N10: =ROUND($L10/INDEX(Items!$F$5:$F$62,MATCH($E10,Items!$A$5:$A$62,0)),4) -> 0.0075
A11: 1 | B11: Classic | C11: Eyelash Extension | D11: K_LASH | E11: Facial Tissue | F11: =INDEX(Items!$B$5:$B$62,MATCH($E11,Items!$A$5:$A$62,0)) -> DISPOSABLES & CLINIC CONSUMABLES | G11: =INDEX(Items!$C$5:$C$62,MATCH($E11,Items!$A$5:$A$62,0)) -> Bulk | H11: Auto-deduct | I11: N | J11: =SUMIFS(Kits!$C$5:$C$163,Kits!$A$5:$A$163,$D11,Kits!$B$5:$B$163,$E11) -> 4 | K11: =INDEX(Services!$F$5:$F$85,MATCH($A11,Services!$A$5:$A$85,0)) -> 1 | L11: =IF($H11="Auto-deduct",IF($G11="Countable",ROUNDUP($J11*IF($I11="Y",$K11,1),0),ROUND($J11*IF($I11="Y",$K11,1),1)),$J11) -> 4 | M11: =INDEX(Items!$E$5:$E$62,MATCH($E11,Items!$A$5:$A$62,0)) -> sheet | N11: =ROUND($L11/INDEX(Items!$F$5:$F$62,MATCH($E11,Items!$A$5:$A$62,0)),4) -> 0.02
A12: 1 | B12: Classic | C12: Eyelash Extension | D12: K_LASH | E12: Transpore Tape | F12: =INDEX(Items!$B$5:$B$62,MATCH($E12,Items!$A$5:$A$62,0)) -> DISPOSABLES & CLINIC CONSUMABLES | G12: =INDEX(Items!$C$5:$C$62,MATCH($E12,Items!$A$5:$A$62,0)) -> Bulk | H12: Auto-deduct | I12: N | J12: =SUMIFS(Kits!$C$5:$C$163,Kits!$A$5:$A$163,$D12,Kits!$B$5:$B$163,$E12) -> 30 | K12: =INDEX(Services!$F$5:$F$85,MATCH($A12,Services!$A$5:$A$85,0)) -> 1 | L12: =IF($H12="Auto-deduct",IF($G12="Countable",ROUNDUP($J12*IF($I12="Y",$K12,1),0),ROUND($J12*IF($I12="Y",$K12,1),1)),$J12) -> 30 | M12: =INDEX(Items!$E$5:$E$62,MATCH($E12,Items!$A$5:$A$62,0)) -> cm | N12: =ROUND($L12/INDEX(Items!$F$5:$F$62,MATCH($E12,Items!$A$5:$A$62,0)),4) -> 0.0328
A13: 1 | B13: Classic | C13: Eyelash Extension | D13: K_LASH | E13: Alcohol | F13: =INDEX(Items!$B$5:$B$62,MATCH($E13,Items!$A$5:$A$62,0)) -> DISPOSABLES & CLINIC CONSUMABLES | G13: =INDEX(Items!$C$5:$C$62,MATCH($E13,Items!$A$5:$A$62,0)) -> Bulk | H13: Auto-deduct | I13: N | J13: =SUMIFS(Kits!$C$5:$C$163,Kits!$A$5:$A$163,$D13,Kits!$B$5:$B$163,$E13) -> 5 | K13: =INDEX(Services!$F$5:$F$85,MATCH($A13,Services!$A$5:$A$85,0)) -> 1 | L13: =IF($H13="Auto-deduct",IF($G13="Countable",ROUNDUP($J13*IF($I13="Y",$K13,1),0),ROUND($J13*IF($I13="Y",$K13,1),1)),$J13) -> 5 | M13: =INDEX(Items!$E$5:$E$62,MATCH($E13,Items!$A$5:$A$62,0)) -> mL | N13: =ROUND($L13/INDEX(Items!$F$5:$F$62,MATCH($E13,Items!$A$5:$A$62,0)),4) -> 0.01
A14: 1 | B14: Classic | C14: Eyelash Extension | D14: K_LASH | E14: Wipes | F14: =INDEX(Items!$B$5:$B$62,MATCH($E14,Items!$A$5:$A$62,0)) -> DISPOSABLES & CLINIC CONSUMABLES | G14: =INDEX(Items!$C$5:$C$62,MATCH($E14,Items!$A$5:$A$62,0)) -> Bulk | H14: Auto-deduct | I14: N | J14: =SUMIFS(Kits!$C$5:$C$163,Kits!$A$5:$A$163,$D14,Kits!$B$5:$B$163,$E14) -> 2 | K14: =INDEX(Services!$F$5:$F$85,MATCH($A14,Services!$A$5:$A$85,0)) -> 1 | L14: =IF($H14="Auto-deduct",IF($G14="Countable",ROUNDUP($J14*IF($I14="Y",$K14,1),0),ROUND($J14*IF($I14="Y",$K14,1),1)),$J14) -> 2 | M14: =INDEX(Items!$E$5:$E$62,MATCH($E14,Items!$A$5:$A$62,0)) -> pc | N14: =ROUND($L14/INDEX(Items!$F$5:$F$62,MATCH($E14,Items!$A$5:$A$62,0)),4) -> 0.025
A15: 2 | B15: Hybrid | C15: Eyelash Extension | D15: K_HYG | E15: Disposable Mask | F15: =INDEX(Items!$B$5:$B$62,MATCH($E15,Items!$A$5:$A$62,0)) -> DISPOSABLES & CLINIC CONSUMABLES | G15: =INDEX(Items!$C$5:$C$62,MATCH($E15,Items!$A$5:$A$62,0)) -> Countable | H15: Auto-deduct | I15: N | J15: =SUMIFS(Kits!$C$5:$C$163,Kits!$A$5:$A$163,$D15,Kits!$B$5:$B$163,$E15) -> 1 | K15: =INDEX(Services!$F$5:$F$85,MATCH($A15,Services!$A$5:$A$85,0)) -> 1 | L15: =IF($H15="Auto-deduct",IF($G15="Countable",ROUNDUP($J15*IF($I15="Y",$K15,1),0),ROUND($J15*IF($I15="Y",$K15,1),1)),$J15) -> 1 | M15: =INDEX(Items!$E$5:$E$62,MATCH($E15,Items!$A$5:$A$62,0)) -> pc | N15: =ROUND($L15/INDEX(Items!$F$5:$F$62,MATCH($E15,Items!$A$5:$A$62,0)),4) -> 1
A16: 2 | B16: Hybrid | C16: Eyelash Extension | D16: K_HYG | E16: Latex Gloves (Small) | F16: =INDEX(Items!$B$5:$B$62,MATCH($E16,Items!$A$5:$A$62,0)) -> DISPOSABLES & CLINIC CONSUMABLES | G16: =INDEX(Items!$C$5:$C$62,MATCH($E16,Items!$A$5:$A$62,0)) -> Countable | H16: Auto-deduct | I16: N | J16: =SUMIFS(Kits!$C$5:$C$163,Kits!$A$5:$A$163,$D16,Kits!$B$5:$B$163,$E16) -> 1 | K16: =INDEX(Services!$F$5:$F$85,MATCH($A16,Services!$A$5:$A$85,0)) -> 1 | L16: =IF($H16="Auto-deduct",IF($G16="Countable",ROUNDUP($J16*IF($I16="Y",$K16,1),0),ROUND($J16*IF($I16="Y",$K16,1),1)),$J16) -> 1 | M16: =INDEX(Items!$E$5:$E$62,MATCH($E16,Items!$A$5:$A$62,0)) -> pair | N16: =ROUND($L16/INDEX(Items!$F$5:$F$62,MATCH($E16,Items!$A$5:$A$62,0)),4) -> 1
... A856: 81 | B856: BT w/ BFR Thigh | C856: Body Tightening / Fat Reduction | D856: K_BT_BFR | E856: Facial Tissue | F856: =INDEX(Items!$B$5:$B$62,MATCH($E856,Items!$A$5:$A$62,0)) -> DISPOSABLES & CLINIC CONSUMABLES | G856: =INDEX(Items!$C$5:$C$62,MATCH($E856,Items!$A$5:$A$62,0)) -> Bulk | H856: Auto-deduct | I856: N | J856: =SUMIFS(Kits!$C$5:$C$163,Kits!$A$5:$A$163,$D856,Kits!$B$5:$B$163,$E856) -> 4 | K856: =INDEX(Services!$F$5:$F$85,MATCH($A856,Services!$A$5:$A$85,0)) -> 1 | L856: =IF($H856="Auto-deduct",IF($G856="Countable",ROUNDUP($J856*IF($I856="Y",$K856,1),0),ROUND($J856*IF($I856="Y",$K856,1),1)),$J856) -> 4 | M856: =INDEX(Items!$E$5:$E$62,MATCH($E856,Items!$A$5:$A$62,0)) -> sheet | N856: =ROUND($L856/INDEX(Items!$F$5:$F$62,MATCH($E856,Items!$A$5:$A$62,0)),4) -> 0.02

Sheet Matrix
A1: Matrix: auto-deduct quantity per service (rows) by consumable (columns), grouped by inventory category
A2: Values are in each item's usage unit (see Items). Blank = not used. Aftercare/retail items are excluded here (see Service_Consumables).
D3: MEDICAL / INJECTION SUPPLIES | E3: MEDICAL / INJECTION SUPPLIES | F3: MEDICAL / INJECTION SUPPLIES | G3: MEDICAL / INJECTION SUPPLIES | H3: MEDICAL / INJECTION SUPPLIES | I3: MEDICAL / INJECTION SUPPLIES | J3: MEDICAL / INJECTION SUPPLIES | K3: MEDICAL / INJECTION SUPPLIES | L3: MEDICAL / INJECTION SUPPLIES | M3: MEDICAL / INJECTION SUPPLIES | N3: MEDICAL / INJECTION SUPPLIES | O3: DISPOSABLES & CLINIC CONSUMABLES | P3: DISPOSABLES & CLINIC CONSUMABLES | Q3: DISPOSABLES & CLINIC CONSUMABLES | R3: DISPOSABLES & CLINIC CONSUMABLES | S3: DISPOSABLES & CLINIC CONSUMABLES | T3: DISPOSABLES & CLINIC CONSUMABLES | U3: DISPOSABLES & CLINIC CONSUMABLES | V3: DISPOSABLES & CLINIC CONSUMABLES | W3: DISPOSABLES & CLINIC CONSUMABLES | X3: DISPOSABLES & CLINIC CONSUMABLES | Y3: DISPOSABLES & CLINIC CONSUMABLES | Z3: DISPOSABLES & CLINIC CONSUMABLES | AA3: DISPOSABLES & CLINIC CONSUMABLES | AB3: DISPOSABLES & CLINIC CONSUMABLES | AC3: DISPOSABLES & CLINIC CONSUMABLES | AD3: DISPOSABLES & CLINIC CONSUMABLES | AE3: FACIAL / TREATMENT PREP PRODUCTS | AF3: FACIAL / TREATMENT PREP PRODUCTS | AG3: FACIAL / TREATMENT PREP PRODUCTS | AH3: FACIAL / TREATMENT PREP PRODUCTS | AI3: FACIAL / TREATMENT PREP PRODUCTS | AJ3: FACIAL / TREATMENT PREP PRODUCTS | AK3: FACIAL / TREATMENT PREP PRODUCTS | AL3: FACIAL TREATMENT PRODUCTS (PROFESSIONAL USE) | AM3: FACIAL TREATMENT PRODUCTS (PROFESSIONAL USE) | AN3: FACIAL TREATMENT PRODUCTS (PROFESSIONAL USE) | AO3: FACIAL TREATMENT PRODUCTS (PROFESSIONAL USE) | AP3: FACIAL TREATMENT PRODUCTS (PROFESSIONAL USE) | AQ3: FACIAL TREATMENT PRODUCTS (PROFESSIONAL USE) | AR3: FACIAL TREATMENT PRODUCTS (PROFESSIONAL USE) | AS3: FACIAL TREATMENT PRODUCTS (PROFESSIONAL USE) | AT3: FACIAL TREATMENT PRODUCTS (PROFESSIONAL USE) | AU3: SKINCARE PRODUCTS (RETAIL / AFTERCARE) | AV3: SKINCARE PRODUCTS (RETAIL / AFTERCARE) | AW3: SKINCARE PRODUCTS (RETAIL / AFTERCARE) | AX3: SKINCARE PRODUCTS (RETAIL / AFTERCARE) | AY3: SKINCARE PRODUCTS (RETAIL / AFTERCARE) | AZ3: SKINCARE PRODUCTS (RETAIL / AFTERCARE) | BA3: SKINCARE PRODUCTS (RETAIL / AFTERCARE) | BB3: SKINCARE PRODUCTS (RETAIL / AFTERCARE) | BC3: SOAPS & CLEANSERS | BD3: SOAPS & CLEANSERS | BE3: SOAPS & CLEANSERS | BF3: SOAPS & CLEANSERS | BG3: SOAPS & CLEANSERS | BH3: TOOLS / EQUIPMENT / MISC | BI3: TOOLS / EQUIPMENT / MISC
C4: # services using this item | D4: =COUNTIF(D6:D86,">0") -> 2 | E4: =COUNTIF(E6:E86,">0") -> 7 | F4: =COUNTIF(F6:F86,">0") -> 8 | G4: =COUNTIF(G6:G86,">0") -> 2 | H4: =COUNTIF(H6:H86,">0") -> 6 | I4: =COUNTIF(I6:I86,">0") -> 6 | J4: =COUNTIF(J6:J86,">0") -> 6 | K4: =COUNTIF(K6:K86,">0") -> 2 | ... BI4: =COUNTIF(BI6:BI86,">0") -> 11
A5: ID | B5: Family | C5: Service | D5: 1cc Syringe | E5: 3cc Syringe | F5: 10cc Syringe | G5: Scalp Vein Set | H5: Baby Needle | I5: 1cc BD Needle | J5: Cannula | K5: Cartridge | L5: Test Tube | M5: Sterile Water | N5: Macroset (IV Set) | O5: Bouffant Cap | P5: Disposable Mask | Q5: Latex Gloves (Small) | R5: Latex Gloves (Medium) | S5: Facial Tissue | T5: Toilet Tissue | U5: CV/RF Tissue | V5: Cotton Roll | W5: Cotton Applicator | X5: Tongue Depressor | Y5: Transpore Tape | Z5: Cling Wrap | AA5: Gauze | AB5: Sterile Gauze | AC5: Wipes | AD5: Alcohol | AE5: Toner | AF5: Clarifying Toner | AG5: Acne Buster Toner | AH5: Glycolic Peeling Toner | AI5: Hypo Liquid Soap | AJ5: Facial Scrub | AK5: Hand Soap | AL5: Gold Mask | AM5: Collagen Gold Mask | AN5: Hydra Moist Mask | AO5: Frozen Mask | AP5: RF Cream | AQ5: Ultrasound Gel | AR5: Capsugen | AS5: Nee Revive | AT5: Nee Bright | AU5: Acne Topical Solution | AV5: Erythromycin | AW5: Whitening Cream | AX5: Hydrocortisone | AY5: Glycolic Peel Solution | AZ5: Underarm Serum | BA5: Sunblock Gel | BB5: Deodorant Spray | BC5: Luna Verde Soap | BD5: Tea Tree Soap | BE5: Barley Soap | BF5: Mallow Soap 100g | BG5: Mallow Soap 300g | BH5: Shaver | BI5: EMLA Cream (Topical Anesthetic)
A6: =Services!A5 -> 1 | B6: =Services!B5 -> Eyelash Extension | C6: =Services!C5 -> Classic | D6: =SUMIFS(Service_Consumables!$L$5:$L$856,Service_Consumables!$A$5:$A$856,$A6,Service_Consumables!$E$5:$E$856,D$5,Service_Consumables!$H$5:$H$856,"Auto-deduct") -> 0 | E6: =SUMIFS(Service_Consumables!$L$5:$L$856,Service_Consumables!$A$5:$A$856,$A6,Service_Consumables!$E$5:$E$856,E$5,Service_Consumables!$H$5:$H$856,"Auto-deduct") -> 0 | F6: =SUMIFS(Service_Consumables!$L$5:$L$856,Service_Consumables!$A$5:$A$856,$A6,Service_Consumables!$E$5:$E$856,F$5,Service_Consumables!$H$5:$H$856,"Auto-deduct") -> 0 | G6: =SUMIFS(Service_Consumables!$L$5:$L$856,Service_Consumables!$A$5:$A$856,$A6,Service_Consumables!$E$5:$E$856,G$5,Service_Consumables!$H$5:$H$856,"Auto-deduct") -> 0 | H6: =SUMIFS(Service_Consumables!$L$5:$L$856,Service_Consumables!$A$5:$A$856,$A6,Service_Consumables!$E$5:$E$856,H$5,Service_Consumables!$H$5:$H$856,"Auto-deduct") -> 0 | I6: =SUMIFS(Service_Consumables!$L$5:$L$856,Service_Consumables!$A$5:$A$856,$A6,Service_Consumables!$E$5:$E$856,I$5,Service_Consumables!$H$5:$H$856,"Auto-deduct") -> 0 | J6: =SUMIFS(Service_Consumables!$L$5:$L$856,Service_Consumables!$A$5:$A$856,$A6,Service_Consumables!$E$5:$E$856,J$5,Service_Consumables!$H$5:$H$856,"Auto-deduct") -> 0 | K6: =SUMIFS(Service_Consumables!$L$5:$L$856,Service_Consumables!$A$5:$A$856,$A6,Service_Consumables!$E$5:$E$856,K$5,Service_Consumables!$H$5:$H$856,"Auto-deduct") -> 0 | ... BI6: =SUMIFS(Service_Consumables!$L$5:$L$856,Service_Consumables!$A$5:$A$856,$A6,Service_Consumables!$E$5:$E$856,BI$5,Service_Consumables!$H$5:$H$856,"Auto-deduct") -> 0
A7: =Services!A6 -> 2 | B7: =Services!B6 -> Eyelash Extension | C7: =Services!C6 -> Hybrid | D7: =SUMIFS(Service_Consumables!$L$5:$L$856,Service_Consumables!$A$5:$A$856,$A7,Service_Consumables!$E$5:$E$856,D$5,Service_Consumables!$H$5:$H$856,"Auto-deduct") -> 0 | E7: =SUMIFS(Service_Consumables!$L$5:$L$856,Service_Consumables!$A$5:$A$856,$A7,Service_Consumables!$E$5:$E$856,E$5,Service_Consumables!$H$5:$H$856,"Auto-deduct") -> 0 | F7: =SUMIFS(Service_Consumables!$L$5:$L$856,Service_Consumables!$A$5:$A$856,$A7,Service_Consumables!$E$5:$E$856,F$5,Service_Consumables!$H$5:$H$856,"Auto-deduct") -> 0 | G7: =SUMIFS(Service_Consumables!$L$5:$L$856,Service_Consumables!$A$5:$A$856,$A7,Service_Consumables!$E$5:$E$856,G$5,Service_Consumables!$H$5:$H$856,"Auto-deduct") -> 0 | H7: =SUMIFS(Service_Consumables!$L$5:$L$856,Service_Consumables!$A$5:$A$856,$A7,Service_Consumables!$E$5:$E$856,H$5,Service_Consumables!$H$5:$H$856,"Auto-deduct") -> 0 | I7: =SUMIFS(Service_Consumables!$L$5:$L$856,Service_Consumables!$A$5:$A$856,$A7,Service_Consumables!$E$5:$E$856,I$5,Service_Consumables!$H$5:$H$856,"Auto-deduct") -> 0 | J7: =SUMIFS(Service_Consumables!$L$5:$L$856,Service_Consumables!$A$5:$A$856,$A7,Service_Consumables!$E$5:$E$856,J$5,Service_Consumables!$H$5:$H$856,"Auto-deduct") -> 0 | K7: =SUMIFS(Service_Consumables!$L$5:$L$856,Service_Consumables!$A$5:$A$856,$A7,Service_Consumables!$E$5:$E$856,K$5,Service_Consumables!$H$5:$H$856,"Auto-deduct") -> 0 | ... BI7: =SUMIFS(Service_Consumables!$L$5:$L$856,Service_Consumables!$A$5:$A$856,$A7,Service_Consumables!$E$5:$E$856,BI$5,Service_Consumables!$H$5:$H$856,"Auto-deduct") -> 0
A8: =Services!A7 -> 3 | B8: =Services!B7 -> Eyelash Extension | C8: =Services!C7 -> Volume | D8: =SUMIFS(Service_Consumables!$L$5:$L$856,Service_Consumables!$A$5:$A$856,$A8,Service_Consumables!$E$5:$E$856,D$5,Service_Consumables!$H$5:$H$856,"Auto-deduct") -> 0 | E8: =SUMIFS(Service_Consumables!$L$5:$L$856,Service_Consumables!$A$5:$A$856,$A8,Service_Consumables!$E$5:$E$856,E$5,Service_Consumables!$H$5:$H$856,"Auto-deduct") -> 0 | F8: =SUMIFS(Service_Consumables!$L$5:$L$856,Service_Consumables!$A$5:$A$856,$A8,Service_Consumables!$E$5:$E$856,F$5,Service_Consumables!$H$5:$H$856,"Auto-deduct") -> 0 | G8: =SUMIFS(Service_Consumables!$L$5:$L$856,Service_Consumables!$A$5:$A$856,$A8,Service_Consumables!$E$5:$E$856,G$5,Service_Consumables!$H$5:$H$856,"Auto-deduct") -> 0 | H8: =SUMIFS(Service_Consumables!$L$5:$L$856,Service_Consumables!$A$5:$A$856,$A8,Service_Consumables!$E$5:$E$856,H$5,Service_Consumables!$H$5:$H$856,"Auto-deduct") -> 0 | I8: =SUMIFS(Service_Consumables!$L$5:$L$856,Service_Consumables!$A$5:$A$856,$A8,Service_Consumables!$E$5:$E$856,I$5,Service_Consumables!$H$5:$H$856,"Auto-deduct") -> 0 | J8: =SUMIFS(Service_Consumables!$L$5:$L$856,Service_Consumables!$A$5:$A$856,$A8,Service_Consumables!$E$5:$E$856,J$5,Service_Consumables!$H$5:$H$856,"Auto-deduct") -> 0 | K8: =SUMIFS(Service_Consumables!$L$5:$L$856,Service_Consumables!$A$5:$A$856,$A8,Service_Consumables!$E$5:$E$856,K$5,Service_Consumables!$H$5:$H$856,"Auto-deduct") -> 0 | ... BI8: =SUMIFS(Service_Consumables!$L$5:$L$856,Service_Consumables!$A$5:$A$856,$A8,Service_Consumables!$E$5:$E$856,BI$5,Service_Consumables!$H$5:$H$856,"Auto-deduct") -> 0
A9: =Services!A8 -> 4 | B9: =Services!B8 -> Eyelash Extension | C9: =Services!C8 -> Mega Volume | D9: =SUMIFS(Service_Consumables!$L$5:$L$856,Service_Consumables!$A$5:$A$856,$A9,Service_Consumables!$E$5:$E$856,D$5,Service_Consumables!$H$5:$H$856,"Auto-deduct") -> 0 | E9: =SUMIFS(Service_Consumables!$L$5:$L$856,Service_Consumables!$A$5:$A$856,$A9,Service_Consumables!$E$5:$E$856,E$5,Service_Consumables!$H$5:$H$856,"Auto-deduct") -> 0 | F9: =SUMIFS(Service_Consumables!$L$5:$L$856,Service_Consumables!$A$5:$A$856,$A9,Service_Consumables!$E$5:$E$856,F$5,Service_Consumables!$H$5:$H$856,"Auto-deduct") -> 0 | G9: =SUMIFS(Service_Consumables!$L$5:$L$856,Service_Consumables!$A$5:$A$856,$A9,Service_Consumables!$E$5:$E$856,G$5,Service_Consumables!$H$5:$H$856,"Auto-deduct") -> 0 | H9: =SUMIFS(Service_Consumables!$L$5:$L$856,Service_Consumables!$A$5:$A$856,$A9,Service_Consumables!$E$5:$E$856,H$5,Service_Consumables!$H$5:$H$856,"Auto-deduct") -> 0 | I9: =SUMIFS(Service_Consumables!$L$5:$L$856,Service_Consumables!$A$5:$A$856,$A9,Service_Consumables!$E$5:$E$856,I$5,Service_Consumables!$H$5:$H$856,"Auto-deduct") -> 0 | J9: =SUMIFS(Service_Consumables!$L$5:$L$856,Service_Consumables!$A$5:$A$856,$A9,Service_Consumables!$E$5:$E$856,J$5,Service_Consumables!$H$5:$H$856,"Auto-deduct") -> 0 | K9: =SUMIFS(Service_Consumables!$L$5:$L$856,Service_Consumables!$A$5:$A$856,$A9,Service_Consumables!$E$5:$E$856,K$5,Service_Consumables!$H$5:$H$856,"Auto-deduct") -> 0 | ... BI9: =SUMIFS(Service_Consumables!$L$5:$L$856,Service_Consumables!$A$5:$A$856,$A9,Service_Consumables!$E$5:$E$856,BI$5,Service_Consumables!$H$5:$H$856,"Auto-deduct") -> 0
A10: =Services!A9 -> 5 | B10: =Services!B9 -> Eyelash Extension | C10: =Services!C9 -> Infill | D10: =SUMIFS(Service_Consumables!$L$5:$L$856,Service_Consumables!$A$5:$A$856,$A10,Service_Consumables!$E$5:$E$856,D$5,Service_Consumables!$H$5:$H$856,"Auto-deduct") -> 0 | E10: =SUMIFS(Service_Consumables!$L$5:$L$856,Service_Consumables!$A$5:$A$856,$A10,Service_Consumables!$E$5:$E$856,E$5,Service_Consumables!$H$5:$H$856,"Auto-deduct") -> 0 | F10: =SUMIFS(Service_Consumables!$L$5:$L$856,Service_Consumables!$A$5:$A$856,$A10,Service_Consumables!$E$5:$E$856,F$5,Service_Consumables!$H$5:$H$856,"Auto-deduct") -> 0 | G10: =SUMIFS(Service_Consumables!$L$5:$L$856,Service_Consumables!$A$5:$A$856,$A10,Service_Consumables!$E$5:$E$856,G$5,Service_Consumables!$H$5:$H$856,"Auto-deduct") -> 0 | H10: =SUMIFS(Service_Consumables!$L$5:$L$856,Service_Consumables!$A$5:$A$856,$A10,Service_Consumables!$E$5:$E$856,H$5,Service_Consumables!$H$5:$H$856,"Auto-deduct") -> 0 | I10: =SUMIFS(Service_Consumables!$L$5:$L$856,Service_Consumables!$A$5:$A$856,$A10,Service_Consumables!$E$5:$E$856,I$5,Service_Consumables!$H$5:$H$856,"Auto-deduct") -> 0 | J10: =SUMIFS(Service_Consumables!$L$5:$L$856,Service_Consumables!$A$5:$A$856,$A10,Service_Consumables!$E$5:$E$856,J$5,Service_Consumables!$H$5:$H$856,"Auto-deduct") -> 0 | K10: =SUMIFS(Service_Consumables!$L$5:$L$856,Service_Consumables!$A$5:$A$856,$A10,Service_Consumables!$E$5:$E$856,K$5,Service_Consumables!$H$5:$H$856,"Auto-deduct") -> 0 | ... BI10: =SUMIFS(Service_Consumables!$L$5:$L$856,Service_Consumables!$A$5:$A$856,$A10,Service_Consumables!$E$5:$E$856,BI$5,Service_Consumables!$H$5:$H$856,"Auto-deduct") -> 0
A11: =Services!A10 -> 6 | B11: =Services!B10 -> Eyelash Extension | C11: =Services!C10 -> Removal | D11: =SUMIFS(Service_Consumables!$L$5:$L$856,Service_Consumables!$A$5:$A$856,$A11,Service_Consumables!$E$5:$E$856,D$5,Service_Consumables!$H$5:$H$856,"Auto-deduct") -> 0 | E11: =SUMIFS(Service_Consumables!$L$5:$L$856,Service_Consumables!$A$5:$A$856,$A11,Service_Consumables!$E$5:$E$856,E$5,Service_Consumables!$H$5:$H$856,"Auto-deduct") -> 0 | F11: =SUMIFS(Service_Consumables!$L$5:$L$856,Service_Consumables!$A$5:$A$856,$A11,Service_Consumables!$E$5:$E$856,F$5,Service_Consumables!$H$5:$H$856,"Auto-deduct") -> 0 | G11: =SUMIFS(Service_Consumables!$L$5:$L$856,Service_Consumables!$A$5:$A$856,$A11,Service_Consumables!$E$5:$E$856,G$5,Service_Consumables!$H$5:$H$856,"Auto-deduct") -> 0 | H11: =SUMIFS(Service_Consumables!$L$5:$L$856,Service_Consumables!$A$5:$A$856,$A11,Service_Consumables!$E$5:$E$856,H$5,Service_Consumables!$H$5:$H$856,"Auto-deduct") -> 0 | I11: =SUMIFS(Service_Consumables!$L$5:$L$856,Service_Consumables!$A$5:$A$856,$A11,Service_Consumables!$E$5:$E$856,I$5,Service_Consumables!$H$5:$H$856,"Auto-deduct") -> 0 | J11: =SUMIFS(Service_Consumables!$L$5:$L$856,Service_Consumables!$A$5:$A$856,$A11,Service_Consumables!$E$5:$E$856,J$5,Service_Consumables!$H$5:$H$856,"Auto-deduct") -> 0 | K11: =SUMIFS(Service_Consumables!$L$5:$L$856,Service_Consumables!$A$5:$A$856,$A11,Service_Consumables!$E$5:$E$856,K$5,Service_Consumables!$H$5:$H$856,"Auto-deduct") -> 0 | ... BI11: =SUMIFS(Service_Consumables!$L$5:$L$856,Service_Consumables!$A$5:$A$856,$A11,Service_Consumables!$E$5:$E$856,BI$5,Service_Consumables!$H$5:$H$856,"Auto-deduct") -> 0
A12: =Services!A11 -> 7 | B12: =Services!B11 -> Threading Services | C12: =Services!C11 -> Eyebrow | D12: =SUMIFS(Service_Consumables!$L$5:$L$856,Service_Consumables!$A$5:$A$856,$A12,Service_Consumables!$E$5:$E$856,D$5,Service_Consumables!$H$5:$H$856,"Auto-deduct") -> 0 | E12: =SUMIFS(Service_Consumables!$L$5:$L$856,Service_Consumables!$A$5:$A$856,$A12,Service_Consumables!$E$5:$E$856,E$5,Service_Consumables!$H$5:$H$856,"Auto-deduct") -> 0 | F12: =SUMIFS(Service_Consumables!$L$5:$L$856,Service_Consumables!$A$5:$A$856,$A12,Service_Consumables!$E$5:$E$856,F$5,Service_Consumables!$H$5:$H$856,"Auto-deduct") -> 0 | G12: =SUMIFS(Service_Consumables!$L$5:$L$856,Service_Consumables!$A$5:$A$856,$A12,Service_Consumables!$E$5:$E$856,G$5,Service_Consumables!$H$5:$H$856,"Auto-deduct") -> 0 | H12: =SUMIFS(Service_Consumables!$L$5:$L$856,Service_Consumables!$A$5:$A$856,$A12,Service_Consumables!$E$5:$E$856,H$5,Service_Consumables!$H$5:$H$856,"Auto-deduct") -> 0 | I12: =SUMIFS(Service_Consumables!$L$5:$L$856,Service_Consumables!$A$5:$A$856,$A12,Service_Consumables!$E$5:$E$856,I$5,Service_Consumables!$H$5:$H$856,"Auto-deduct") -> 0 | J12: =SUMIFS(Service_Consumables!$L$5:$L$856,Service_Consumables!$A$5:$A$856,$A12,Service_Consumables!$E$5:$E$856,J$5,Service_Consumables!$H$5:$H$856,"Auto-deduct") -> 0 | K12: =SUMIFS(Service_Consumables!$L$5:$L$856,Service_Consumables!$A$5:$A$856,$A12,Service_Consumables!$E$5:$E$856,K$5,Service_Consumables!$H$5:$H$856,"Auto-deduct") -> 0 | ... BI12: =SUMIFS(Service_Consumables!$L$5:$L$856,Service_Consumables!$A$5:$A$856,$A12,Service_Consumables!$E$5:$E$856,BI$5,Service_Consumables!$H$5:$H$856,"Auto-deduct") -> 0
A13: =Services!A12 -> 8 | B13: =Services!B12 -> Threading Services | C13: =Services!C12 -> Upper Lip | D13: =SUMIFS(Service_Consumables!$L$5:$L$856,Service_Consumables!$A$5:$A$856,$A13,Service_Consumables!$E$5:$E$856,D$5,Service_Consumables!$H$5:$H$856,"Auto-deduct") -> 0 | E13: =SUMIFS(Service_Consumables!$L$5:$L$856,Service_Consumables!$A$5:$A$856,$A13,Service_Consumables!$E$5:$E$856,E$5,Service_Consumables!$H$5:$H$856,"Auto-deduct") -> 0 | F13: =SUMIFS(Service_Consumables!$L$5:$L$856,Service_Consumables!$A$5:$A$856,$A13,Service_Consumables!$E$5:$E$856,F$5,Service_Consumables!$H$5:$H$856,"Auto-deduct") -> 0 | G13: =SUMIFS(Service_Consumables!$L$5:$L$856,Service_Consumables!$A$5:$A$856,$A13,Service_Consumables!$E$5:$E$856,G$5,Service_Consumables!$H$5:$H$856,"Auto-deduct") -> 0 | H13: =SUMIFS(Service_Consumables!$L$5:$L$856,Service_Consumables!$A$5:$A$856,$A13,Service_Consumables!$E$5:$E$856,H$5,Service_Consumables!$H$5:$H$856,"Auto-deduct") -> 0 | I13: =SUMIFS(Service_Consumables!$L$5:$L$856,Service_Consumables!$A$5:$A$856,$A13,Service_Consumables!$E$5:$E$856,I$5,Service_Consumables!$H$5:$H$856,"Auto-deduct") -> 0 | J13: =SUMIFS(Service_Consumables!$L$5:$L$856,Service_Consumables!$A$5:$A$856,$A13,Service_Consumables!$E$5:$E$856,J$5,Service_Consumables!$H$5:$H$856,"Auto-deduct") -> 0 | K13: =SUMIFS(Service_Consumables!$L$5:$L$856,Service_Consumables!$A$5:$A$856,$A13,Service_Consumables!$E$5:$E$856,K$5,Service_Consumables!$H$5:$H$856,"Auto-deduct") -> 0 | ... BI13: =SUMIFS(Service_Consumables!$L$5:$L$856,Service_Consumables!$A$5:$A$856,$A13,Service_Consumables!$E$5:$E$856,BI$5,Service_Consumables!$H$5:$H$856,"Auto-deduct") -> 0
A14: =Services!A13 -> 9 | B14: =Services!B13 -> Threading Services | C14: =Services!C13 -> Lower Lip | D14: =SUMIFS(Service_Consumables!$L$5:$L$856,Service_Consumables!$A$5:$A$856,$A14,Service_Consumables!$E$5:$E$856,D$5,Service_Consumables!$H$5:$H$856,"Auto-deduct") -> 0 | E14: =SUMIFS(Service_Consumables!$L$5:$L$856,Service_Consumables!$A$5:$A$856,$A14,Service_Consumables!$E$5:$E$856,E$5,Service_Consumables!$H$5:$H$856,"Auto-deduct") -> 0 | F14: =SUMIFS(Service_Consumables!$L$5:$L$856,Service_Consumables!$A$5:$A$856,$A14,Service_Consumables!$E$5:$E$856,F$5,Service_Consumables!$H$5:$H$856,"Auto-deduct") -> 0 | G14: =SUMIFS(Service_Consumables!$L$5:$L$856,Service_Consumables!$A$5:$A$856,$A14,Service_Consumables!$E$5:$E$856,G$5,Service_Consumables!$H$5:$H$856,"Auto-deduct") -> 0 | H14: =SUMIFS(Service_Consumables!$L$5:$L$856,Service_Consumables!$A$5:$A$856,$A14,Service_Consumables!$E$5:$E$856,H$5,Service_Consumables!$H$5:$H$856,"Auto-deduct") -> 0 | I14: =SUMIFS(Service_Consumables!$L$5:$L$856,Service_Consumables!$A$5:$A$856,$A14,Service_Consumables!$E$5:$E$856,I$5,Service_Consumables!$H$5:$H$856,"Auto-deduct") -> 0 | J14: =SUMIFS(Service_Consumables!$L$5:$L$856,Service_Consumables!$A$5:$A$856,$A14,Service_Consumables!$E$5:$E$856,J$5,Service_Consumables!$H$5:$H$856,"Auto-deduct") -> 0 | K14: =SUMIFS(Service_Consumables!$L$5:$L$856,Service_Consumables!$A$5:$A$856,$A14,Service_Consumables!$E$5:$E$856,K$5,Service_Consumables!$H$5:$H$856,"Auto-deduct") -> 0 | ... BI14: =SUMIFS(Service_Consumables!$L$5:$L$856,Service_Consumables!$A$5:$A$856,$A14,Service_Consumables!$E$5:$E$856,BI$5,Service_Consumables!$H$5:$H$856,"Auto-deduct") -> 0
A15: =Services!A14 -> 10 | B15: =Services!B14 -> Threading Services | C15: =Services!C14 -> Combo | D15: =SUMIFS(Service_Consumables!$L$5:$L$856,Service_Consumables!$A$5:$A$856,$A15,Service_Consumables!$E$5:$E$856,D$5,Service_Consumables!$H$5:$H$856,"Auto-deduct") -> 0 | E15: =SUMIFS(Service_Consumables!$L$5:$L$856,Service_Consumables!$A$5:$A$856,$A15,Service_Consumables!$E$5:$E$856,E$5,Service_Consumables!$H$5:$H$856,"Auto-deduct") -> 0 | F15: =SUMIFS(Service_Consumables!$L$5:$L$856,Service_Consumables!$A$5:$A$856,$A15,Service_Consumables!$E$5:$E$856,F$5,Service_Consumables!$H$5:$H$856,"Auto-deduct") -> 0 | G15: =SUMIFS(Service_Consumables!$L$5:$L$856,Service_Consumables!$A$5:$A$856,$A15,Service_Consumables!$E$5:$E$856,G$5,Service_Consumables!$H$5:$H$856,"Auto-deduct") -> 0 | H15: =SUMIFS(Service_Consumables!$L$5:$L$856,Service_Consumables!$A$5:$A$856,$A15,Service_Consumables!$E$5:$E$856,H$5,Service_Consumables!$H$5:$H$856,"Auto-deduct") -> 0 | I15: =SUMIFS(Service_Consumables!$L$5:$L$856,Service_Consumables!$A$5:$A$856,$A15,Service_Consumables!$E$5:$E$856,I$5,Service_Consumables!$H$5:$H$856,"Auto-deduct") -> 0 | J15: =SUMIFS(Service_Consumables!$L$5:$L$856,Service_Consumables!$A$5:$A$856,$A15,Service_Consumables!$E$5:$E$856,J$5,Service_Consumables!$H$5:$H$856,"Auto-deduct") -> 0 | K15: =SUMIFS(Service_Consumables!$L$5:$L$856,Service_Consumables!$A$5:$A$856,$A15,Service_Consumables!$E$5:$E$856,K$5,Service_Consumables!$H$5:$H$856,"Auto-deduct") -> 0 | ... BI15: =SUMIFS(Service_Consumables!$L$5:$L$856,Service_Consumables!$A$5:$A$856,$A15,Service_Consumables!$E$5:$E$856,BI$5,Service_Consumables!$H$5:$H$856,"Auto-deduct") -> 0
A16: =Services!A15 -> 11 | B16: =Services!B15 -> Hair Removal (IPL-HR) | C16: =Services!C15 -> Underarms | D16: =SUMIFS(Service_Consumables!$L$5:$L$856,Service_Consumables!$A$5:$A$856,$A16,Service_Consumables!$E$5:$E$856,D$5,Service_Consumables!$H$5:$H$856,"Auto-deduct") -> 0 | E16: =SUMIFS(Service_Consumables!$L$5:$L$856,Service_Consumables!$A$5:$A$856,$A16,Service_Consumables!$E$5:$E$856,E$5,Service_Consumables!$H$5:$H$856,"Auto-deduct") -> 0 | F16: =SUMIFS(Service_Consumables!$L$5:$L$856,Service_Consumables!$A$5:$A$856,$A16,Service_Consumables!$E$5:$E$856,F$5,Service_Consumables!$H$5:$H$856,"Auto-deduct") -> 0 | G16: =SUMIFS(Service_Consumables!$L$5:$L$856,Service_Consumables!$A$5:$A$856,$A16,Service_Consumables!$E$5:$E$856,G$5,Service_Consumables!$H$5:$H$856,"Auto-deduct") -> 0 | H16: =SUMIFS(Service_Consumables!$L$5:$L$856,Service_Consumables!$A$5:$A$856,$A16,Service_Consumables!$E$5:$E$856,H$5,Service_Consumables!$H$5:$H$856,"Auto-deduct") -> 0 | I16: =SUMIFS(Service_Consumables!$L$5:$L$856,Service_Consumables!$A$5:$A$856,$A16,Service_Consumables!$E$5:$E$856,I$5,Service_Consumables!$H$5:$H$856,"Auto-deduct") -> 0 | J16: =SUMIFS(Service_Consumables!$L$5:$L$856,Service_Consumables!$A$5:$A$856,$A16,Service_Consumables!$E$5:$E$856,J$5,Service_Consumables!$H$5:$H$856,"Auto-deduct") -> 0 | K16: =SUMIFS(Service_Consumables!$L$5:$L$856,Service_Consumables!$A$5:$A$856,$A16,Service_Consumables!$E$5:$E$856,K$5,Service_Consumables!$H$5:$H$856,"Auto-deduct") -> 0 | ... BI16: =SUMIFS(Service_Consumables!$L$5:$L$856,Service_Consumables!$A$5:$A$856,$A16,Service_Consumables!$E$5:$E$856,BI$5,Service_Consumables!$H$5:$H$856,"Auto-deduct") -> 0
